Workbook
Name Slicer_Age__category: #N/A
Name Slicer_Gender: #N/A
Name Slicer_Product_Category: #N/A

Sheet Retail_Sales_Dataset_Overview
A4: Transaction ID | B4: Day | C4: Month | D4: Year | E4: Day name | F4: Month name | G4: Year name | H4: Date | I4: Customer ID | J4: Gender | K4: Age category | L4: Age | M4: Product Category | N4: Quantity | O4: Price per Unit | P4: Total Sales | Q4: Commission 2023 | R4: Commission 2024
A5: 1 | B5: 24 | C5: 11 | D5: 2023 | E5: Friday | F5: November | G5: 2023 | H5: 45254 | I5: CUST001 | J5: Male | K5: Adult | L5: 34 | M5: Beauty | N5: 3 | O5: 50 | P5: 150 | Q5: 2.25 | R5: 3
A6: 2 | B6: 27 | C6: 2 | D6: 2023 | E6: Monday | F6: February | G6: 2023 | H6: 44984 | I6: CUST002 | J6: Female | K6: Young Adult | L6: 26 | M6: Beauty | N6: 2 | O6: 500 | P6: 1000 | Q6: 15 | R6: 20
A7: 3 | B7: 13 | C7: 1 | D7: 2023 | E7: Friday | F7: January | G7: 2023 | H7: 44939 | I7: CUST003 | J7: Male | K7: Adult | L7: 50 | M7: Beauty | N7: 1 | O7: 30 | P7: 30 | Q7: 0.45 | R7: 0.6
A8: 4 | B8: 21 | C8: 5 | D8: 2023 | E8: Sunday | F8: May | G8: 2023 | H8: 45067 | I8: CUST004 | J8: Male | K8: Adult | L8: 37 | M8: Beauty | N8: 1 | O8: 500 | P8: 500 | Q8: 7.5 | R8: 10
A9: 5 | B9: 6 | C9: 5 | D9: 2023 | E9: Saturday | F9: May | G9: 2023 | H9: 45052 | I9: CUST005 | J9: Male | K9: Adult | L9: 30 | M9: Beauty | N9: 2 | O9: 50 | P9: 100 | Q9: 1.5 | R9: 2
A10: 6 | B10: 25 | C10: 4 | D10: 2023 | E10: Tuesday | F10: April | G10: 2023 | H10: 45041 | I10: CUST006 | J10: Female | K10: Adult | L10: 45 | M10: Beauty | N10: 1 | O10: 30 | P10: 30 | Q10: 0.45 | R10: 0.6
A11: 7 | B11: 13 | C11: 3 | D11: 2023 | E11: Monday | F11: March | G11: 2023 | H11: 44998 | I11: CUST007 | J11: Male | K11: Adult | L11: 46 | M11: Beauty | N11: 2 | O11: 25 | P11: 50 | Q11: 0.75 | R11: 1
A12: 8 | B12: 22 | C12: 2 | D12: 2023 | E12: Wednesday | F12: February | G12: 2023 | H12: 44979 | I12: CUST008 | J12: Male | K12: Adult | L12: 30 | M12: Beauty | N12: 4 | O12: 25 | P12: 100 | Q12: 1.5 | R12: 2
A13: 9 | B13: 13 | C13: 12 | D13: 2023 | E13: Wednesday | F13: December | G13: 2023 | H13: 45273 | I13: CUST009 | J13: Male | K13: Senior | L13: 63 | M13: Beauty | N13: 2 | O13: 300 | P13: 600 | Q13: 9 | R13: 12
A14: 10 | B14: 7 | C14: 10 | D14: 2023 | E14: Saturday | F14: October | G14: 2023 | H14: 45206 | I14: CUST010 | J14: Female | K14: Senior | L14: 52 | M14: Beauty | N14: 4 | O14: 50 | P14: 200 | Q14: 3 | R14: 4
A15: 11 | B15: 14 | C15: 2 | D15: 2023 | E15: Tuesday | F15: February | G15: 2023 | H15: 44971 | I15: CUST011 | J15: Male | K15: Young Adult | L15: 23 | M15: Beauty | N15: 2 | O15: 50 | P15: 100 | Q15: 1.5 | R15: 2
A16: 12 | B16: 30 | C16: 10 | D16: 2023 | E16: Monday | F16: October | G16: 2023 | H16: 45229 | I16: CUST012 | J16: Male | K16: Adult | L16: 35 | M16: Beauty | N16: 3 | O16: 25 | P16: 75 | Q16: 1.125 | R16: 1.5
... A1004: 1000 | B1004: 12 | C1004: 4 | D1004: 2023 | E1004: Wednesday | F1004: April | G1004: 2023 | H1004: 45028 | I1004: CUST1000 | J1004: Male | K1004: Adult | L1004: 47 | M1004: Electronics | N1004: 4 | O1004: 30 | P1004: 120 | Q1004: 1.8 | R1004: 2.4

Sheet FILTER_SUM_AVERAGE
I2: Total commission for 2023 | K2: =SUM(Q:Q) -> 4800
I4: Total commission for 2024 | K4: =SUM(R:R) -> 6400
I6: Total commission for 2023 & 2024 | K6: =SUM(K2+K4) -> 11200
I8: Average commission for 2023 | K8: =AVERAGE(Q:Q) -> 7.2507553
I10: Average commission for 2024 | K10: =AVERAGE(R:R) -> 9.6676737
A12: Transaction ID | B12: Day | C12: Month | D12: Year | E12: Day name | F12: Month name | G12: Year name | H12: Date | I12: Customer ID | J12: Gender | K12: Age category | L12: Age | M12: Product Category | N12: Quantity | O12: Price per Unit | P12: Total Sales | Q12: Commission 2023 | R12: Commission 2024 | S12: Commission 2025
A13: 1 | B13: 24 | C13: 11 | D13: 2023 | E13: Friday | F13: November | G13: 2023 | H13: 45254 | I13: CUST001 | J13: Male | K13: Adult | L13: 34 | M13: Beauty | N13: 3 | O13: 50 | P13: 150 | Q13: 2.25 | R13: 3
A14: 2 | B14: 27 | C14: 2 | D14: 2023 | E14: Monday | F14: February | G14: 2023 | H14: 44984 | I14: CUST002 | J14: Female | K14: Young Adult | L14: 26 | M14: Beauty | N14: 2 | O14: 500 | P14: 1000 | Q14: 15 | R14: 20
A15: 3 | B15: 13 | C15: 1 | D15: 2023 | E15: Friday | F15: January | G15: 2023 | H15: 44939 | I15: CUST003 | J15: Male | K15: Adult | L15: 50 | M15: Beauty | N15: 1 | O15: 30 | P15: 30 | Q15: 0.45 | R15: 0.6
A16: 4 | B16: 21 | C16: 5 | D16: 2023 | E16: Sunday | F16: May | G16: 2023 | H16: 45067 | I16: CUST004 | J16: Male | K16: Adult | L16: 37 | M16: Beauty | N16: 1 | O16: 500 | P16: 500 | Q16: 7.5 | R16: 10
A17: 5 | B17: 6 | C17: 5 | D17: 2023 | E17: Saturday | F17: May | G17: 2023 | H17: 45052 | I17: CUST005 | J17: Male | K17: Adult | L17: 30 | M17: Beauty | N17: 2 | O17: 50 | P17: 100 | Q17: 1.5 | R17: 2
A18: 6 | B18: 25 | C18: 4 | D18: 2023 | E18: Tuesday | F18: April | G18: 2023 | H18: 45041 | I18: CUST006 | J18: Female | K18: Adult | L18: 45 | M18: Beauty | N18: 1 | O18: 30 | P18: 30 | Q18: 0.45 | R18: 0.6
A19: 7 | B19: 13 | C19: 3 | D19: 2023 | E19: Monday | F19: March | G19: 2023 | H19: 44998 | I19: CUST007 | J19: Male | K19: Adult | L19: 46 | M19: Beauty | N19: 2 | O19: 25 | P19: 50 | Q19: 0.75 | R19: 1
A20: 8 | B20: 22 | C20: 2 | D20: 2023 | E20: Wednesday | F20: February | G20: 2023 | H20: 44979 | I20: CUST008 | J20: Male | K20: Adult | L20: 30 | M20: Beauty | N20: 4 | O20: 25 | P20: 100 | Q20: 1.5 | R20: 2
A21: 9 | B21: 13 | C21: 12 | D21: 2023 | E21: Wednesday | F21: December | G21: 2023 | H21: 45273 | I21: CUST009 | J21: Male | K21: Senior | L21: 63 | M21: Beauty | N21: 2 | O21: 300 | P21: 600 | Q21: 9 | R21: 12
A22: 10 | B22: 7 | C22: 10 | D22: 2023 | E22: Saturday | F22: October | G22: 2023 | H22: 45206 | I22: CUST010 | J22: Female | K22: Senior | L22: 52 | M22: Beauty | N22: 4 | O22: 50 | P22: 200 | Q22: 3 | R22: 4
A23: 11 | B23: 14 | C23: 2 | D23: 2023 | E23: Tuesday | F23: February | G23: 2023 | H23: 44971 | I23: CUST011 | J23: Male | K23: Young Adult | L23: 23 | M23: Beauty | N23: 2 | O23: 50 | P23: 100 | Q23: 1.5 | R23: 2
A24: 12 | B24: 30 | C24: 10 | D24: 2023 | E24: Monday | F24: October | G24: 2023 | H24: 45229 | I24: CUST012 | J24: Male | K24: Adult | L24: 35 | M24: Beauty | N24: 3 | O24: 25 | P24: 75 | Q24: 1.125 | R24: 1.5
... A674: 998 | B674: 29 | C674: 10 | D674: 2023 | E674: Sunday | F674: October | G674: 2023 | H674: 45228 | I674: CUST998 | J674: Female | K674: Young Adult | L674: 23 | M674: Beauty | N674: 4 | O674: 25 | P674: 100 | Q674: 1.5 | R674: 2

Sheet SUM_IF_&_CONDITIONAL_FORMATTING
I2: Rate | M2: =V22 -> Quantity | N2: =W22 -> Quantity
K3: =T23 -> Product Category | L3: =U23 -> Sales | M3: =V23 -> Male | N3: =W23 -> Female
H4: Commission 2023 | I4: 0.015 | K4: =T24 -> Beauty | L4: =U24 -> 143515 | M4: =V24 -> 353 | N4: =W24 -> 418
H5: Commission 2024 | I5: 0.02 | K5: =T25 -> Electronics | L5: =U25 -> 156905 | M5: =V25 -> 403 | N5: =W25 -> 439
K6: =T26 -> Clothing | L6: =U26 -> 155580 | M6: =V26 -> 453 | N6: =W26 -> 441
K7: =T27 -> All products | L7: =U27 -> 456000 | M7: =V27 -> 0 | N7: =W27 -> 0
A11: Transaction ID | B11: Day | C11: Month | D11: Year | E11: Day name | F11: Month name | G11: Year name | H11: Date | I11: Customer ID | J11: Gender | K11: Age Category | L11: Age | M11: Product Category | N11: Quantity | O11: Price per Unit | P11: Total Sales | Q11: Commission 2023 | R11: Commission 2024
A12: 1 | B12: =DAY(H12) -> 24 | C12: =MONTH(H12) -> 11 | D12: =YEAR(H12) -> 2023 | E12: =TEXT(H12,"DDDD") -> Friday | F12: =TEXT(H12,"MMMM") -> November | G12: =TEXT(H12,"YYYY") -> 2023 | H12: 45254 | I12: CUST001 | J12: Male | K12: {=_xlfn.IFS(L12>50,"Senior", L12>=30,"Adult", L12<30,"Young Adult")} -> Adult | L12: 34 | M12: Beauty | N12: 3 | O12: 50 | P12: =O12*N12 -> 150 | Q12: =P12*$I$4 -> 2.25 | R12: =P12*$I$5 -> 3
A13: 2 | B13: =DAY(H13) -> 27 | C13: =MONTH(H13) -> 2 | D13: =YEAR(H13) -> 2023 | E13: =TEXT(H13,"DDDD") -> Monday | F13: =TEXT(H13,"MMMM") -> February | G13: =TEXT(H13,"YYYY") -> 2023 | H13: 44984 | I13: CUST002 | J13: Female | K13: {=_xlfn.IFS(L13>50,"Senior", L13>=30,"Adult", L13<30,"Young Adult")} -> Young Adult | L13: 26 | M13: Clothing | N13: 2 | O13: 500 | P13: =O13*N13 -> 1000 | Q13: =P13*$I$4 -> 15 | R13: =P13*$I$5 -> 20
A14: 3 | B14: =DAY(H14) -> 13 | C14: =MONTH(H14) -> 1 | D14: =YEAR(H14) -> 2023 | E14: =TEXT(H14,"DDDD") -> Friday | F14: =TEXT(H14,"MMMM") -> January | G14: =TEXT(H14,"YYYY") -> 2023 | H14: 44939 | I14: CUST003 | J14: Male | K14: {=_xlfn.IFS(L14>50,"Senior", L14>=30,"Adult", L14<30,"Young Adult")} -> Adult | L14: 50 | M14: Electronics | N14: 1 | O14: 30 | P14: =O14*N14 -> 30 | Q14: =P14*$I$4 -> 0.45 | R14: =P14*$I$5 -> 0.6
A15: 4 | B15: =DAY(H15) -> 21 | C15: =MONTH(H15) -> 5 | D15: =YEAR(H15) -> 2023 | E15: =TEXT(H15,"DDDD") -> Sunday | F15: =TEXT(H15,"MMMM") -> May | G15: =TEXT(H15,"YYYY") -> 2023 | H15: 45067 | I15: CUST004 | J15: Male | K15: {=_xlfn.IFS(L15>50,"Senior", L15>=30,"Adult", L15<30,"Young Adult")} -> Adult | L15: 37 | M15: Clothing | N15: 1 | O15: 500 | P15: =O15*N15 -> 500 | Q15: =P15*$I$4 -> 7.5 | R15: =P15*$I$5 -> 10
A16: 5 | B16: =DAY(H16) -> 6 | C16: =MONTH(H16) -> 5 | D16: =YEAR(H16) -> 2023 | E16: =TEXT(H16,"DDDD") -> Saturday | F16: =TEXT(H16,"MMMM") -> May | G16: =TEXT(H16,"YYYY") -> 2023 | H16: 45052 | I16: CUST005 | J16: Male | K16: {=_xlfn.IFS(L16>50,"Senior", L16>=30,"Adult", L16<30,"Young Adult")} -> Adult | L16: 30 | M16: Beauty | N16: 2 | O16: 50 | P16: =O16*N16 -> 100 | Q16: =P16*$I$4 -> 1.5 | R16: =P16*$I$5 -> 2
A17: 6 | B17: =DAY(H17) -> 25 | C17: =MONTH(H17) -> 4 | D17: =YEAR(H17) -> 2023 | E17: =TEXT(H17,"DDDD") -> Tuesday | F17: =TEXT(H17,"MMMM") -> April | G17: =TEXT(H17,"YYYY") -> 2023 | H17: 45041 | I17: CUST006 | J17: Female | K17: {=_xlfn.IFS(L17>50,"Senior", L17>=30,"Adult", L17<30,"Young Adult")} -> Adult | L17: 45 | M17: Beauty | N17: 1 | O17: 30 | P17: =O17*N17 -> 30 | Q17: =P17*$I$4 -> 0.45 | R17: =P17*$I$5 -> 0.6
A18: 7 | B18: =DAY(H18) -> 13 | C18: =MONTH(H18) -> 3 | D18: =YEAR(H18) -> 2023 | E18: =TEXT(H18,"DDDD") -> Monday | F18: =TEXT(H18,"MMMM") -> March | G18: =TEXT(H18,"YYYY") -> 2023 | H18: 44998 | I18: CUST007 | J18: Male | K18: {=_xlfn.IFS(L18>50,"Senior", L18>=30,"Adult", L18<30,"Young Adult")} -> Adult | L18: 46 | M18: Clothing | N18: 2 | O18: 25 | P18: =O18*N18 -> 50 | Q18: =P18*$I$4 -> 0.75 | R18: =P18*$I$5 -> 1
A19: 8 | B19: =DAY(H19) -> 22 | C19: =MONTH(H19) -> 2 | D19: =YEAR(H19) -> 2023 | E19: =TEXT(H19,"DDDD") -> Wednesday | F19: =TEXT(H19,"MMMM") -> February | G19: =TEXT(H19,"YYYY") -> 2023 | H19: 44979 | I19: CUST008 | J19: Male | K19: {=_xlfn.IFS(L19>50,"Senior", L19>=30,"Adult", L19<30,"Young Adult")} -> Adult | L19: 30 | M19: Electronics | N19: 4 | O19: 25 | P19: =O19*N19 -> 100 | Q19: =P19*$I$4 -> 1.5 | R19: =P19*$I$5 -> 2
A20: 9 | B20: =DAY(H20) -> 13 | C20: =MONTH(H20) -> 12 | D20: =YEAR(H20) -> 2023 | E20: =TEXT(H20,"DDDD") -> Wednesday | F20: =TEXT(H20,"MMMM") -> December | G20: =TEXT(H20,"YYYY") -> 2023 | H20: 45273 | I20: CUST009 | J20: Male | K20: {=_xlfn.IFS(L20>50,"Senior", L20>=30,"Adult", L20<30,"Young Adult")} -> Senior | L20: 63 | M20: Electronics | N20: 2 | O20: 300 | P20: =O20*N20 -> 600 | Q20: =P20*$I$4 -> 9 | R20: =P20*$I$5 -> 12
A21: 10 | B21: =DAY(H21) -> 7 | C21: =MONTH(H21) -> 10 | D21: =YEAR(H21) -> 2023 | E21: =TEXT(H21,"DDDD") -> Saturday | F21: =TEXT(H21,"MMMM") -> October | G21: =TEXT(H21,"YYYY") -> 2023 | H21: 45206 | I21: CUST010 | J21: Female | K21: {=_xlfn.IFS(L21>50,"Senior", L21>=30,"Adult", L21<30,"Young Adult")} -> Senior | L21: 52 | M21: Clothing | N21: 4 | O21: 50 | P21: =O21*N21 -> 200 | Q21: =P21*$I$4 -> 3 | R21: =P21*$I$5 -> 4
A22: 11 | B22: =DAY(H22) -> 14 | C22: =MONTH(H22) -> 2 | D22: =YEAR(H22) -> 2023 | E22: =TEXT(H22,"DDDD") -> Tuesday | F22: =TEXT(H22,"MMMM") -> February | G22: =TEXT(H22,"YYYY") -> 2023 | H22: 44971 | I22: CUST011 | J22: Male | K22: {=_xlfn.IFS(L22>50,"Senior", L22>=30,"Adult", L22<30,"Young Adult")} -> Young Adult | L22: 23 | M22: Clothing | N22: 2 | O22: 50 | P22: =O22*N22 -> 100 | Q22: =P22*$I$4 -> 1.5 | R22: =P22*$I$5 -> 2 | V22: Quantity | W22: Quantity
A23: 12 | B23: =DAY(H23) -> 30 | C23: =MONTH(H23) -> 10 | D23: =YEAR(H23) -> 2023 | E23: =TEXT(H23,"DDDD") -> Monday | F23: =TEXT(H23,"MMMM") -> October | G23: =TEXT(H23,"YYYY") -> 2023 | H23: 45229 | I23: CUST012 | J23: Male | K23: {=_xlfn.IFS(L23>50,"Senior", L23>=30,"Adult", L23<30,"Young Adult")} -> Adult | L23: 35 | M23: Beauty | N23: 3 | O23: 25 | P23: =O23*N23 -> 75 | Q23: =P23*$I$4 -> 1.125 | R23: =P23*$I$5 -> 1.5 | T23: Product Category | U23: Sales | V23: Male | W23: Female
A24: 13 | B24: =DAY(H24) -> 5 | C24: =MONTH(H24) -> 8 | D24: =YEAR(H24) -> 2023 | E24: =TEXT(H24,"DDDD") -> Saturday | F24: =TEXT(H24,"MMMM") -> August | G24: =TEXT(H24,"YYYY") -> 2023 | H24: 45143 | I24: CUST013 | J24: Male | K24: {=_xlfn.IFS(L24>50,"Senior", L24>=30,"Adult", L24<30,"Young Adult")} -> Young Adult | L24: 22 | M24: Electronics | N24: 3 | O24: 500 | P24: =O24*N24 -> 1500 | Q24: =P24*$I$4 -> 22.5 | R24: =P24*$I$5 -> 30 | T24: Beauty | U24: =SUMIF(M11:M1010, "beauty",P11:P1020) -> 143515 | V24: =SUMIFS(N12:N1011, J12:J1011, "Male",M12:M1011, "Beauty") -> 353 | W24: =SUMIFS(N12:N1011, J12:J1011,"Female",M12:M1011,"Beauty") -> 418
A25: 14 | B25: =DAY(H25) -> 17 | C25: =MONTH(H25) -> 1 | D25: =YEAR(H25) -> 2023 | E25: =TEXT(H25,"DDDD") -> Tuesday | F25: =TEXT(H25,"MMMM") -> January | G25: =TEXT(H25,"YYYY") -> 2023 | H25: 44943 | I25: CUST014 | J25: Male | K25: {=_xlfn.IFS(L25>50,"Senior", L25>=30,"Adult", L25<30,"Young Adult")} -> Senior | L25: 64 | M25: Clothing | N25: 4 | O25: 30 | P25: =O25*N25 -> 120 | Q25: =P25*$I$4 -> 1.8 | R25: =P25*$I$5 -> 2.4 | T25: Electronics | U25: =SUMIF(M11:M1021, "electronics",P11:P1020) -> 156905 | V25: =SUMIFS(N24:N1011, J24:J1011, "Male",M24:M1011, "Electronics") -> 403 | W25: =SUMIFS(N24:N1011, J24:J1011,"Female",M24:M1011,"Electronics") -> 439
A26: 15 | B26: =DAY(H26) -> 16 | C26: =MONTH(H26) -> 1 | D26: =YEAR(H26) -> 2023 | E26: =TEXT(H26,"DDDD") -> Monday | F26: =TEXT(H26,"MMMM") -> January | G26: =TEXT(H26,"YYYY") -> 2023 | H26: 44942 | I26: CUST015 | J26: Female | K26: {=_xlfn.IFS(L26>50,"Senior", L26>=30,"Adult", L26<30,"Young Adult")} -> Adult | L26: 42 | M26: Electronics | N26: 4 | O26: 500 | P26: =O26*N26 -> 2000 | Q26: =P26*$I$4 -> 30 | R26: =P26*$I$5 -> 40 | T26: Clothing | U26: =SUMIF(M12:M1011, "clothing",P12:P1011) -> 155580 | V26: =SUMIFS(N12:N1011, J12:J1011, "Male",M12:M1011, "Clothing") -> 453 | W26: =SUMIFS(N12:N1011, J12:J1011,"Female",M12:M1011,"Clothing") -> 441
A27: 16 | B27: =DAY(H27) -> 17 | C27: =MONTH(H27) -> 2 | D27: =YEAR(H27) -> 2023 | E27: =TEXT(H27,"DDDD") -> Friday | F27: =TEXT(H27,"MMMM") -> February | G27: =TEXT(H27,"YYYY") -> 2023 | H27: 44974 | I27: CUST016 | J27: Male | K27: {=_xlfn.IFS(L27>50,"Senior", L27>=30,"Adult", L27<30,"Young Adult")} -> Young Adult | L27: 19 | M27: Clothing | N27: 3 | O27: 500 | P27: =O27*N27 -> 1500 | Q27: =P27*$I$4 -> 22.5 | R27: =P27*$I$5 -> 30 | T27: All products | U27: =SUM(U24:U26) -> 456000
A28: 17 | B28: =DAY(H28) -> 22 | C28: =MONTH(H28) -> 4 | D28: =YEAR(H28) -> 2023 | E28: =TEXT(H28,"DDDD") -> Saturday | F28: =TEXT(H28,"MMMM") -> April | G28: =TEXT(H28,"YYYY") -> 2023 | H28: 45038 | I28: CUST017 | J28: Female | K28: {=_xlfn.IFS(L28>50,"Senior", L28>=30,"Adult", L28<30,"Young Adult")} -> Young Adult | L28: 27 | M28: Clothing | N28: 4 | O28: 25 | P28: =O28*N28 -> 100 | Q28: =P28*$I$4 -> 1.5 | R28: =P28*$I$5 -> 2
A29: 18 | B29: =DAY(H29) -> 30 | C29: =MONTH(H29) -> 4 | D29: =YEAR(H29) -> 2023 | E29: =TEXT(H29,"DDDD") -> Sunday | F29: =TEXT(H29,"MMMM") -> April | G29: =TEXT(H29,"YYYY") -> 2023 | H29: 45046 | I29: CUST018 | J29: Female | K29: {=_xlfn.IFS(L29>50,"Senior", L29>=30,"Adult", L29<30,"Young Adult")} -> Adult | L29: 47 | M29: Electronics | N29: 2 | O29: 25 | P29: =O29*N29 -> 50 | Q29: =P29*$I$4 -> 0.75 | R29: =P29*$I$5 -> 1
A30: 19 | B30: =DAY(H30) -> 16 | C30: =MONTH(H30) -> 9 | D30: =YEAR(H30) -> 2023 | E30: =TEXT(H30,"DDDD") -> Saturday | F30: =TEXT(H30,"MMMM") -> September | G30: =TEXT(H30,"YYYY") -> 2023 | H30: 45185 | I30: CUST019 | J30: Female | K30: {=_xlfn.IFS(L30>50,"Senior", L30>=30,"Adult", L30<30,"Young Adult")} -> Senior | L30: 62 | M30: Clothing | N30: 2 | O30: 25 | P30: =O30*N30 -> 50 | Q30: =P30*$I$4 -> 0.75 | R30: =P30*$I$5 -> 1
A31: 20 | B31: =DAY(H31) -> 5 | C31: =MONTH(H31) -> 11 | D31: =YEAR(H31) -> 2023 | E31: =TEXT(H31,"DDDD") -> Sunday | F31: =TEXT(H31,"MMMM") -> November | G31: =TEXT(H31,"YYYY") -> 2023 | H31: 45235 | I31: CUST020 | J31: Male | K31: {=_xlfn.IFS(L31>50,"Senior", L31>=30,"Adult", L31<30,"Young Adult")} -> Young Adult | L31: 22 | M31: Clothing | N31: 3 | O31: 300 | P31: =O31*N31 -> 900 | Q31: =P31*$I$4 -> 13.5 | R31: =P31*$I$5 -> 18
A32: 21 | B32: =DAY(H32) -> 14 | C32: =MONTH(H32) -> 1 | D32: =YEAR(H32) -> 2023 | E32: =TEXT(H32,"DDDD") -> Saturday | F32: =TEXT(H32,"MMMM") -> January | G32: =TEXT(H32,"YYYY") -> 2023 | H32: 44940 | I32: CUST021 | J32: Female | K32: {=_xlfn.IFS(L32>50,"Senior", L32>=30,"Adult", L32<30,"Young Adult")} -> Adult | L32: 50 | M32: Beauty | N32: 1 | O32: 500 | P32: =O32*N32 -> 500 | Q32: =P32*$I$4 -> 7.5 | R32: =P32*$I$5 -> 10
A33: 22 | B33: =DAY(H33) -> 15 | C33: =MONTH(H33) -> 10 | D33: =YEAR(H33) -> 2023 | E33: =TEXT(H33,"DDDD") -> Sunday | F33: =TEXT(H33,"MMMM") -> October | G33: =TEXT(H33,"YYYY") -> 2023 | H33: 45214 | I33: CUST022 | J33: Male | K33: {=_xlfn.IFS(L33>50,"Senior", L33>=30,"Adult", L33<30,"Young Adult")} -> Young Adult | L33: 18 | M33: Clothing | N33: 2 | O33: 50 | P33: =O33*N33 -> 100 | Q33: =P33*$I$4 -> 1.5 | R33: =P33*$I$5 -> 2
A34: 23 | B34: =DAY(H34) -> 12 | C34: =MONTH(H34) -> 4 | D34: =YEAR(H34) -> 2023 | E34: =TEXT(H34,"DDDD") -> Wednesday | F34: =TEXT(H34,"MMMM") -> April | G34: =TEXT(H34,"YYYY") -> 2023 | H34: 45028 | I34: CUST023 | J34: Female | K34: {=_xlfn.IFS(L34>50,"Senior", L34>=30,"Adult", L34<30,"Young Adult")} -> Adult | L34: 35 | M34: Clothing | N34: 4 | O34: 30 | P34: =O34*N34 -> 120 | Q34: =P34*$I$4 -> 1.8 | R34: =P34*$I$5 -> 2.4
A35: 24 | B35: =DAY(H35) -> 29 | C35: =MONTH(H35) -> 11 | D35: =YEAR(H35) -> 2023 | E35: =TEXT(H35,"DDDD") -> Wednesday | F35: =TEXT(H35,"MMMM") -> November | G35: =TEXT(H35,"YYYY") -> 2023 | H35: 45259 | I35: CUST024 | J35: Female | K35: {=_xlfn.IFS(L35>50,"Senior", L35>=30,"Adult", L35<30,"Young Adult")} -> Adult | L35: 49 | M35: Clothing | N35: 1 | O35: 300 | P35: =O35*N35 -> 300 | Q35: =P35*$I$4 -> 4.5 | R35: =P35*$I$5 -> 6
A36: 25 | B36: =DAY(H36) -> 26 | C36: =MONTH(H36) -> 12 | D36: =YEAR(H36) -> 2023 | E36: =TEXT(H36,"DDDD") -> Tuesday | F36: =TEXT(H36,"MMMM") -> December | G36: =TEXT(H36,"YYYY") -> 2023 | H36: 45286 | I36: CUST025 | J36: Female | K36: {=_xlfn.IFS(L36>50,"Senior", L36>=30,"Adult", L36<30,"Young Adult")} -> Senior | L36: 64 | M36: Beauty | N36: 1 | O36: 50 | P36: =O36*N36 -> 50 | Q36: =P36*$I$4 -> 0.75 | R36: =P36*$I$5 -> 1
A37: 26 | B37: =DAY(H37) -> 7 | C37: =MONTH(H37) -> 10 | D37: =YEAR(H37) -> 2023 | E37: =TEXT(H37,"DDDD") -> Saturday | F37: =TEXT(H37,"MMMM") -> October | G37: =TEXT(H37,"YYYY") -> 2023 | H37: 45206 | I37: CUST026 | J37: Female | K37: {=_xlfn.IFS(L37>50,"Senior", L37>=30,"Adult", L37<30,"Young Adult")} -> Young Adult | L37: 28 | M37: Electronics | N37: 2 | O37: 500 | P37: =O37*N37 -> 1000 | Q37: =P37*$I$4 -> 15 | R37: =P37*$I$5 -> 20
A38: 27 | B38: =DAY(H38) -> 3 | C38: =MONTH(H38) -> 8 | D38: =YEAR(H38) -> 2023 | E38: =TEXT(H38,"DDDD") -> Thursday | F38: =TEXT(H38,"MMMM") -> August | G38: =TEXT(H38,"YYYY") -> 2023 | H38: 45141 | I38: CUST027 | J38: Female | K38: {=_xlfn.IFS(L38>50,"Senior", L38>=30,"Adult", L38<30,"Young Adult")} -> Adult | L38: 38 | M38: Beauty | N38: 2 | O38: 25 | P38: =O38*N38 -> 50 | Q38: =P38*$I$4 -> 0.75 | R38: =P38*$I$5 -> 1
A39: 28 | B39: =DAY(H39) -> 23 | C39: =MONTH(H39) -> 4 | D39: =YEAR(H39) -> 2023 | E39: =TEXT(H39,"DDDD") -> Sunday | F39: =TEXT(H39,"MMMM") -> April | G39: =TEXT(H39,"YYYY") -> 2023 | H39: 45039 | I39: CUST028 | J39: Female | K39: {=_xlfn.IFS(L39>50,"Senior", L39>=30,"Adult", L39<30,"Young Adult")} -> Adult | L39: 43 | M39: Beauty | N39: 1 | O39: 500 | P39: =O39*N39 -> 500 | Q39: =P39*$I$4 -> 7.5 | R39: =P39*$I$5 -> 10
... A530: 519 | B530: =DAY(H530) -> 23 | C530: =MONTH(H530) -> 1 | D530: =YEAR(H530) -> 2023 | E530: =TEXT(H530,"DDDD") -> Monday | F530: =TEXT(H530,"MMMM") -> January | G530: =TEXT(H530,"YYYY") -> 2023 | H530: 44949 | I530: CUST519 | J530: Female | K530: {=_xlfn.IFS(L530>50,"Senior", L530>=30,"Adult", L530<30,"Young Adult")} -> Adult | L530: 36 | M530: Electronics | N530: 4 | O530: 30 | P530: =O530*N530 -> 120 | Q530: =P530*$I$4 -> 1.8 | R530: =P530*$I$5 -> 2.4
A531: 520 | B531: =DAY(H531) -> 29 | C531: =MONTH(H531) -> 12 | D531: =YEAR(H531) -> 2023 | E531: =TEXT(H531,"DDDD") -> Friday | F531: =TEXT(H531,"MMMM") -> December | G531: =TEXT(H531,"YYYY") -> 2023 | H531: 45289 | I531: CUST520 | J531: Female | K531: {=_xlfn.IFS(L531>50,"Senior", L531>=30,"Adult", L531<30,"Young Adult")} -> Adult | L531: 49 | M531: Electronics | N531: 4 | O531: 25 | P531: =O531*N531 -> 100 | Q531: =P531*#REF! -> #REF! | R531: =P531*#REF! -> #REF!
A532: 521 | B532: =DAY(H532) -> 12 | C532: =MONTH(H532) -> 8 | D532: =YEAR(H532) -> 2023 | E532: =TEXT(H532,"DDDD") -> Saturday | F532: =TEXT(H532,"MMMM") -> August | G532: =TEXT(H532,"YYYY") -> 2023 | H532: 45150 | I532: CUST521 | J532: Female | K532: {=_xlfn.IFS(L532>50,"Senior", L532>=30,"Adult", L532<30,"Young Adult")} -> Adult | L532: 47 | M532: Clothing | N532: 4 | O532: 30 | P532: =O532*N532 -> 120 | Q532: =P532*#REF! -> #REF! | R532: =P532*#REF! -> #REF!
A533: 522 | B533: =DAY(H533) -> 1 | C533: =MONTH(H533) -> 1 | D533: =YEAR(H533) -> 2023 | E533: =TEXT(H533,"DDDD") -> Sunday | F533: =TEXT(H533,"MMMM") -> January | G533: =TEXT(H533,"YYYY") -> 2023 | H533: 44927 | I533: CUST522 | J533: Male | K533: {=_xlfn.IFS(L533>50,"Senior", L533>=30,"Adult", L533<30,"Young Adult")} -> Adult | L533: 46 | M533: Beauty | N533: 3 | O533: 500 | P533: =O533*N533 -> 1500 | Q533: =P533*$I$4 -> 22.5 | R533: =P533*$I$5 -> 30
A534: 523 | B534: =DAY(H534) -> 24 | C534: =MONTH(H534) -> 9 | D534: =YEAR(H534) -> 2023 | E534: =TEXT(H534,"DDDD") -> Sunday | F534: =TEXT(H534,"MMMM") -> September | G534: =TEXT(H534,"YYYY") -> 2023 | H534: 45193 | I534: CUST523 | J534: Female | K534: {=_xlfn.IFS(L534>50,"Senior", L534>=30,"Adult", L534<30,"Young Adult")} -> Senior | L534: 62 | M534: Electronics | N534: 1 | O534: 300 | P534: =O534*N534 -> 300 | Q534: =P534*#REF! -> #REF! | R534: =P534*#REF! -> #REF!
...

Sheet VLOOKOUT_CONCATENATE
A11: Transaction ID | B11: Total Sales | C11: Product category | D11: Concatenate
A12: 10 | B12: {=VLOOKUP(A12, 'SUM_IF_&_CONDITIONAL_FORMATTING'!A12:Q1011,COLUMN('SUM_IF_&_CONDITIONAL_FORMATTING'!P:P), FALSE)} -> 200 | C12: =VLOOKUP(A12,'SUM_IF_&_CONDITIONAL_FORMATTING'!A12:Q1011, 13, FALSE) -> Clothing | D12: =_xlfn.CONCAT(B12," ",C12) -> 200 Clothing
A13: 15 | B13: {=VLOOKUP(A13, 'SUM_IF_&_CONDITIONAL_FORMATTING'!A13:Q1012,COLUMN('SUM_IF_&_CONDITIONAL_FORMATTING'!P:P), FALSE)} -> 2000 | C13: =VLOOKUP(A13,'SUM_IF_&_CONDITIONAL_FORMATTING'!A13:Q1012, 13, FALSE) -> Electronics | D13: =_xlfn.CONCAT(B13," ",C13) -> 2000 Electronics
A14: 25 | B14: {=VLOOKUP(A14, 'SUM_IF_&_CONDITIONAL_FORMATTING'!A14:Q1013,COLUMN('SUM_IF_&_CONDITIONAL_FORMATTING'!P:P), FALSE)} -> 50 | C14: =VLOOKUP(A14,'SUM_IF_&_CONDITIONAL_FORMATTING'!A14:Q1013, 13, FALSE) -> Beauty | D14: =_xlfn.CONCAT(B14," ",C14) -> 50 Beauty
A15: 30 | B15: {=VLOOKUP(A15, 'SUM_IF_&_CONDITIONAL_FORMATTING'!A15:Q1014,COLUMN('SUM_IF_&_CONDITIONAL_FORMATTING'!P:P), FALSE)} -> 900 | C15: =VLOOKUP(A15,'SUM_IF_&_CONDITIONAL_FORMATTING'!A15:Q1014, 13, FALSE) -> Beauty | D15: =_xlfn.CONCAT(B15," ",C15) -> 900 Beauty
A16: 54 | B16: {=VLOOKUP(A16, 'SUM_IF_&_CONDITIONAL_FORMATTING'!A16:Q1015,COLUMN('SUM_IF_&_CONDITIONAL_FORMATTING'!P:P), FALSE)} -> 1500 | C16: =VLOOKUP(A16,'SUM_IF_&_CONDITIONAL_FORMATTING'!A16:Q1015, 13, FALSE) -> Electronics | D16: =_xlfn.CONCAT(B16," ",C16) -> 1500 Electronics
A17: 55 | B17: {=VLOOKUP(A17, 'SUM_IF_&_CONDITIONAL_FORMATTING'!A17:Q1016,COLUMN('SUM_IF_&_CONDITIONAL_FORMATTING'!P:P), FALSE)} -> 120 | C17: =VLOOKUP(A17,'SUM_IF_&_CONDITIONAL_FORMATTING'!A17:Q1016, 13, FALSE) -> Beauty | D17: =_xlfn.CONCAT(B17," ",C17) -> 120 Beauty
A18: 67 | B18: {=VLOOKUP(A18, 'SUM_IF_&_CONDITIONAL_FORMATTING'!A18:Q1017,COLUMN('SUM_IF_&_CONDITIONAL_FORMATTING'!P:P), FALSE)} -> 1200 | C18: =VLOOKUP(A18,'SUM_IF_&_CONDITIONAL_FORMATTING'!A18:Q1017, 13, FALSE) -> Beauty | D18: =_xlfn.CONCAT(B18," ",C18) -> 1200 Beauty
A19: 89 | B19: {=VLOOKUP(A19, 'SUM_IF_&_CONDITIONAL_FORMATTING'!A19:Q1018,COLUMN('SUM_IF_&_CONDITIONAL_FORMATTING'!P:P), FALSE)} -> 2000 | C19: =VLOOKUP(A19,'SUM_IF_&_CONDITIONAL_FORMATTING'!A19:Q1018, 13, FALSE) -> Electronics | D19: =_xlfn.CONCAT(B19," ",C19) -> 2000 Electronics
A20: 100 | B20: {=VLOOKUP(A20, 'SUM_IF_&_CONDITIONAL_FORMATTING'!A20:Q1019,COLUMN('SUM_IF_&_CONDITIONAL_FORMATTING'!P:P), FALSE)} -> 30 | C20: =VLOOKUP(A20,'SUM_IF_&_CONDITIONAL_FORMATTING'!A20:Q1019, 13, FALSE) -> Electronics | D20: =_xlfn.CONCAT(B20," ",C20) -> 30 Electronics

Sheet Visualization
A11: Sum of Total Sales | B11: Gender
A12: Product Category | B12: Female | C12: Male | D12: Grand Total
A13: Beauty | B13: 0.16410088 | C13: 0.150625 | D13: 0.31472588
A14: Clothing | B14: 0.17823465 | C14: 0.16294956 | D14: 0.34118421
A15: Electronics | B15: 0.16827851 | C15: 0.1758114 | D15: 0.34408991
A16: Grand Total | B16: 0.51061404 | C16: 0.48938596 | D16: 1

Sheet Slicers_Pivot_Table
A11: Sum of Total Sales | B11: Column Labels
B12: Adult | D12: Adult Total | E12: Senior | G12: Senior Total | H12: Young Adult | J12: Young Adult Total | K12: Grand Total
A13: Row Labels | B13: Female | C13: Male | E13: Female | F13: Male | H13: Female | I13: Male
A14: Beauty | B14: 77020 | C14: 69370 | D14: 146390 | E14: 39175 | F14: 41920 | G14: 81095 | H14: 47890 | I14: 44625 | J14: 92515 | K14: 320000
A15: Clothing | B15: 15215 | C15: 14435 | D15: 29650 | E15: 15240 | F15: 11755 | G15: 26995 | H15: 7445 | I15: 6780 | J15: 14225 | K15: 70870
A16: Electronics | B16: 9615 | C16: 13880 | D16: 23495 | E16: 13050 | F16: 12170 | G16: 25220 | H16: 8190 | I16: 8225 | J16: 16415 | K16: 65130
A17: Grand Total | B17: 101850 | C17: 97685 | D17: 199535 | E17: 67465 | F17: 65845 | G17: 133310 | H17: 63525 | I17: 59630 | J17: 123155 | K17: 456000

Sheet Slicers_Pivot_Tabler
A12: Sum of Total Sales | B12: Age 1 | C12: Gender
B13: Adult | D13: Adult Total | E13: Senior | G13: Senior Total | H13: Young Adult | J13: Young Adult Total | K13: Grand Total
A14: Product Category | B14: Female | C14: Male | E14: Female | F14: Male | H14: Female | I14: Male
A15: Beauty | B15: 0.16890351 | C15: 0.15212719 | D15: 0.3210307 | E15: 0.085910088 | F15: 0.091929825 | G15: 0.17783991 | H15: 0.10502193 | I15: 0.097861842 | J15: 0.20288377 | K15: 0.70175439
A16: Clothing | B16: 0.033366228 | C16: 0.031655702 | D16: 0.06502193 | E16: 0.033421053 | F16: 0.025778509 | G16: 0.059199561 | H16: 0.016326754 | I16: 0.014868421 | J16: 0.031195175 | K16: 0.15541667
A17: Electronics | B17: 0.021085526 | C17: 0.030438596 | D17: 0.051524123 | E17: 0.028618421 | F17: 0.026688596 | G17: 0.055307018 | H17: 0.017960526 | I17: 0.018037281 | J17: 0.035997807 | K17: 0.14282895
A18: Grand Total | B18: 0.22335526 | C18: 0.21422149 | D18: 0.43757675 | E18: 0.14794956 | F18: 0.14439693 | G18: 0.29234649 | H18: 0.13930921 | I18: 0.13076754 | J18: 0.27007675 | K18: 1

Sheet Further_Exercises_MAX_FUNCTION
A11: Student name | B11: English | D11: Student name | E11: English | F11: Mathematics | G11: Science | H11: Average | I11: Highest Score Across Subjects
A12: Linda | B12: 90 | D12: Ted | E12: 80 | F12: 75 | G12: 90 | H12: =AVERAGE(E12:G12) -> 81.666667 | I12: =MAX(E12:H12) -> 90
A13: Ted | B13: 80 | D13: Carol | E13: 75 | F13: 85 | G13: 85 | H13: =AVERAGE(E13:G13) -> 81.666667 | I13: =MAX(E13:H13) -> 85
A14: Harry | B14: 80 | D14: Khan | E14: 85 | F14: 75 | G14: 80 | H14: =AVERAGE(E14:G14) -> 80 | I14: =MAX(E14:H14) -> 85
A15: Sarah | B15: 80 | D15: Harry | E15: 80 | F15: 70 | G15: 80 | H15: =AVERAGE(E15:G15) -> 76.666667 | I15: =MAX(E15:H15) -> 80
A16: Carol | B16: 75 | D16: Sarah | E16: 80 | F16: 70 | G16: 80 | H16: =AVERAGE(E16:G16) -> 76.666667 | I16: =MAX(E16:H16) -> 80
A17: John | B17: 65 | D17: John | E17: 65 | F17: 80 | G17: 70 | H17: =AVERAGE(E17:G17) -> 71.666667 | I17: =MAX(E17:H17) -> 80
A18: Khan | B18: 85 | D18: Linda | E18: 90 | F18: 50 | G18: 70 | H18: =AVERAGE(E18:G18) -> 70 | I18: =MAX(E18:H18) -> 90
A19: Edward | B19: 55 | D19: Edward | E19: 55 | F19: 80 | G19: 60 | H19: =AVERAGE(E19:G19) -> 65 | I19: =MAX(E19:H19) -> 80
A20: Mary | B20: 55 | D20: Mary | E20: 55 | F20: 70 | G20: 65 | H20: =AVERAGE(E20:G20) -> 63.333333 | I20: =MAX(E20:H20) -> 70
A21: Thomas | B21: 55 | D21: Thomas | E21: 55 | F21: 30 | G21: 65 | H21: =AVERAGE(E21:G21) -> 50 | I21: =MAX(E21:H21) -> 65
